Workbook

Sheet summary
A1: store_name | B1: Location Results | C1: Total User Reviews | D1: Weighted Average Rating | E1: Straight Average Rating | F1: Standard Deviation
A2: Walmart | B2: =COUNTIFS(raw_data!A:A,A2) -> 2250 | C2: =SUMIFS(raw_data!F:F,raw_data!A:A,A2) -> 5430943 | D2: =SUMIFS(raw_data!G:G,raw_data!A:A,A2)/SUMIFS(raw_data!F:F,raw_data!A:A,A2) -> 3.8668229 | E2: =AVERAGEIFS(raw_data!E:E,raw_data!A:A,A2) -> 3.8710093
A3: Shaw's | B3: =COUNTIFS(raw_data!A:A,A3) -> 120 | C3: =SUMIFS(raw_data!F:F,raw_data!A:A,A3) -> 41831 | D3: =SUMIFS(raw_data!G:G,raw_data!A:A,A3)/SUMIFS(raw_data!F:F,raw_data!A:A,A3) -> 4.0072889 | E3: =AVERAGEIFS(raw_data!E:E,raw_data!A:A,A3) -> 3.9841667
A4: ACME Markets | B4: =COUNTIFS(raw_data!A:A,A4) -> 160 | C4: =SUMIFS(raw_data!F:F,raw_data!A:A,A4) -> 78484 | D4: =SUMIFS(raw_data!G:G,raw_data!A:A,A4)/SUMIFS(raw_data!F:F,raw_data!A:A,A4) -> 4.0287205 | E4: =AVERAGEIFS(raw_data!E:E,raw_data!A:A,A4) -> 3.991875
A5: Safeway | B5: =COUNTIFS(raw_data!A:A,A5) -> 878 | C5: =SUMIFS(raw_data!F:F,raw_data!A:A,A5) -> 707002 | D5: =SUMIFS(raw_data!G:G,raw_data!A:A,A5)/SUMIFS(raw_data!F:F,raw_data!A:A,A5) -> 4.044334 | E5: =AVERAGEIFS(raw_data!E:E,raw_data!A:A,A5) -> 4.0465831
A6: Stop & Shop | B6: =COUNTIFS(raw_data!A:A,A6) -> 344 | C6: =SUMIFS(raw_data!F:F,raw_data!A:A,A6) -> 188070 | D6: =SUMIFS(raw_data!G:G,raw_data!A:A,A6)/SUMIFS(raw_data!F:F,raw_data!A:A,A6) -> 4.0745579 | E6: =AVERAGEIFS(raw_data!E:E,raw_data!A:A,A6) -> 4.047093
A7: King Soopers | B7: =COUNTIFS(raw_data!A:A,A7) -> 93 | C7: =SUMIFS(raw_data!F:F,raw_data!A:A,A7) -> 52087 | D7: =SUMIFS(raw_data!G:G,raw_data!A:A,A7)/SUMIFS(raw_data!F:F,raw_data!A:A,A7) -> 4.0786473 | E7: =AVERAGEIFS(raw_data!E:E,raw_data!A:A,A7) -> 4.0731183
A8: Save-A-Lot | B8: =COUNTIFS(raw_data!A:A,A8) -> 1037 | C8: =SUMIFS(raw_data!F:F,raw_data!A:A,A8) -> 357887 | D8: =SUMIFS(raw_data!G:G,raw_data!A:A,A8)/SUMIFS(raw_data!F:F,raw_data!A:A,A8) -> 4.1060888 | E8: =AVERAGEIFS(raw_data!E:E,raw_data!A:A,A8) -> 4.1379344
A9: Jewel-Osco | B9: =COUNTIFS(raw_data!A:A,A9) -> 174 | C9: =SUMIFS(raw_data!F:F,raw_data!A:A,A9) -> 130501 | D9: =SUMIFS(raw_data!G:G,raw_data!A:A,A9)/SUMIFS(raw_data!F:F,raw_data!A:A,A9) -> 4.1226358 | E9: =AVERAGEIFS(raw_data!E:E,raw_data!A:A,A9) -> 4.1396552
A10: Giant Eagle | B10: =COUNTIFS(raw_data!A:A,A10) -> 210 | C10: =SUMIFS(raw_data!F:F,raw_data!A:A,A10) -> 153626 | D10: =SUMIFS(raw_data!G:G,raw_data!A:A,A10)/SUMIFS(raw_data!F:F,raw_data!A:A,A10) -> 4.1403714 | E10: =AVERAGEIFS(raw_data!E:E,raw_data!A:A,A10) -> 4.0966667
A11: Kroger | B11: =COUNTIFS(raw_data!A:A,A11) -> 906 | C11: =SUMIFS(raw_data!F:F,raw_data!A:A,A11) -> 481392 | D11: =SUMIFS(raw_data!G:G,raw_data!A:A,A11)/SUMIFS(raw_data!F:F,raw_data!A:A,A11) -> 4.1547317 | E11: =AVERAGEIFS(raw_data!E:E,raw_data!A:A,A11) -> 4.15
A12: Fred Meyer | B12: =COUNTIFS(raw_data!A:A,A12) -> 69 | C12: =SUMIFS(raw_data!F:F,raw_data!A:A,A12) -> 64631 | D12: =SUMIFS(raw_data!G:G,raw_data!A:A,A12)/SUMIFS(raw_data!F:F,raw_data!A:A,A12) -> 4.1588077 | E12: =AVERAGEIFS(raw_data!E:E,raw_data!A:A,A12) -> 4.1507246
A13: Food 4 Less | B13: =COUNTIFS(raw_data!A:A,A13) -> 146 | C13: =SUMIFS(raw_data!F:F,raw_data!A:A,A13) -> 97677 | D13: =SUMIFS(raw_data!G:G,raw_data!A:A,A13)/SUMIFS(raw_data!F:F,raw_data!A:A,A13) -> 4.1696582 | E13: =AVERAGEIFS(raw_data!E:E,raw_data!A:A,A13) -> 4.1263889
... A42: Trader Joe's | B42: =COUNTIFS(raw_data!A:A,A42) -> 512 | C42: =SUMIFS(raw_data!F:F,raw_data!A:A,A42) -> 608643 | D42: =SUMIFS(raw_data!G:G,raw_data!A:A,A42)/SUMIFS(raw_data!F:F,raw_data!A:A,A42) -> 4.6192625 | E42: =AVERAGEIFS(raw_data!E:E,raw_data!A:A,A42) -> 4.6330078

Sheet pivot table w stdev
A3: Row Labels | B3: Count of google_store_name | C3: Average of rating | D3: StdDev of rating
A4: Trader Joe's | B4: 512 | C4: 4.6330078 | D4: 0.07312119
A5: Wegmans | B5: 104 | C5: 4.6067308 | D5: 0.061160973
A6: Costco | B6: 390 | C6: 4.5182519 | D6: 0.093615953
A7: Aldi | B7: 841 | C7: 4.483293 | D7: 0.13622372
A8: Vitamin Cottage Natural Grocers | B8: 159 | C8: 4.463522 | D8: 0.11929189
A9: Fresh Market | B9: 159 | C9: 4.4436709 | D9: 0.094722891
A10: Publix | B10: 897 | C10: 4.4410256 | D10: 0.13656442
A11: HEB | B11: 215 | C11: 4.4409302 | D11: 0.19598557
A12: WinCo Foods | B12: 71 | C12: 4.4253521 | D12: 0.10917654
A13: Grocery Outlet | B13: 125 | C13: 4.4216 | D13: 0.12087317
A14: Sprouts Farmers Market | B14: 346 | C14: 4.3930636 | D14: 0.14569526
A15: Stater Bros. Markets | B15: 113 | C15: 4.379646 | D15: 0.17173448
... A45: Grand Total | B45: 15715 | C45: 4.2038927 | D45: 0.27713343

Sheet raw_data
A1: store_name | B1: google_place_id | C1: google_store_name | D1: formatted_address | E1: rating | F1: user_ratings_total | G1: weighted rating
A2: ACME Markets | B2: ChIJr3lhIr-YwokRywwNvLs4NIY | C2: ACME Markets | D2: 1261 E Putnam Ave, Riverside, CT 06878, United States | E2: 4 | F2: 112 | G2: =E2*F2 -> 448
A3: ACME Markets | B3: ChIJ13hp7jiXwokR4H_uJtTJWF0 | C3: ACME Markets | D3: 261 S Ridge St, Rye Brook, NY 10573, United States | E3: 4.1 | F3: 194 | G3: =E3*F3 -> 795.4
A4: ACME Markets | B4: ChIJb1_aXEOhwokROi1CQf1I_pI | C4: ACME Markets | D4: 1201 High Ridge Rd, Stamford, CT 06905, United States | E4: 3.5 | F4: 278 | G4: =E4*F4 -> 973
A5: ACME Markets | B5: ChIJuR2pMDaYwokRb0XP3Kp9Yjk | C5: ACME Markets | D5: 160 West Putnam Avenue, Greenwich, CT 06830, United States | E5: 4 | F5: 180 | G5: =E5*F5 -> 720
A6: ACME Markets | B6: ChIJN5dighCnwokR9GleLHJbLbQ | C6: ACME Markets | D6: 288 Elm St, New Canaan, CT 06840, United States | E6: 4.1 | F6: 162 | G6: =E6*F6 -> 664.2
A7: ACME Markets | B7: ChIJcZ4UY9YAx4kR2PBiFtBJ6DQ | C7: ACME Markets | D7: 1 University Dr, Newark, DE 19702, United States | E7: 3.9 | F7: 645 | G7: =E7*F7 -> 2515.5
A8: ACME Markets | B8: ChIJZUDDSBaqx4kRoZ9UM3zk9C0 | C8: ACME Markets | D8: 100 College Square, Newark, DE 19711, United States | E8: 3.9 | F8: 730 | G8: =E8*F8 -> 2847
A9: ACME Markets | B9: ChIJx8AOaGSpx4kRxqXUaq__iZQ | C9: ACME Markets | D9: 100 Suburban Dr, Newark, DE 19711, United States | E9: 4.1 | F9: 566 | G9: =E9*F9 -> 2320.6
A10: ACME Markets | B10: ChIJV8rUYB8Ax4kR04s4db1B5_M | C10: ACME Markets | D10: 4720 Limestone Rd, Wilmington, DE 19808, United States | E10: 4.2 | F10: 373 | G10: =E10*F10 -> 1566.6
A11: ACME Markets | B11: ChIJvfkeEMUBx4kR6StmNBVg0xI | C11: ACME Markets | D11: 4365 Robert, Kirkwood Hwy, Wilmington, DE 19808, United States | E11: 3.9 | F11: 634 | G11: =E11*F11 -> 2472.6
A12: ACME Markets | B12: ChIJt3LAg_8Bx4kR8k09uSDQBYA | C12: ACME Markets | D12: 1308 Centerville Rd, Wilmington, DE 19808, United States | E12: 4.1 | F12: 998 | G12: =E12*F12 -> 4091.8
A13: ACME Markets | B13: ChIJ3duatDlxx4kRvdsdCBvr9zc | C13: ACME Markets | D13: 236 E Glenwood Ave, Smyrna, DE 19977, United States | E13: 3.9 | F13: 516 | G13: =E13*F13 -> 2012.4
... A601: Aldi | B601: ChIJfSg2EjeEk4cRRvhdMGY47lo | C601: ALDI | D601: 3135 Manawa Center Dr, Council Bluffs, IA 51501, United States | E601: 4.5 | F601: 780 | G601: =E601*F601 -> 3510
A602: Aldi | B602: ChIJt1ueM1YD44cR03UT45mmxaw | C602: Aldi | D602: 907 W Platt St, Maquoketa, IA 52060, United States | G602: =E602*F602 -> 0
A603: Aldi | B603: ChIJw5t3-sRB5IcRzbc5FEa3pLw | C603: Aldi | D603: 1534 S Gilbert St, Iowa City, IA 52240, United States | E603: 4.5 | F603: 2 | G603: =E603*F603 -> 9
A604: Aldi | B604: ChIJg8vlvvny5IcRk9IaiEz9JmQ | C604: ALDI | D604: 1001 50th St, Marion, IA 52302, United States | E604: 4.6 | F604: 649 | G604: =E604*F604 -> 2985.4
A605: Aldi | B605: ChIJEwztgIX65IcRxQ7Zjkl0GKg | C605: ALDI | D605: 5425 Blairs Forest Blvd NE, Cedar Rapids, IA 52402, United States | E605: 4.5 | F605: 891 | G605: =E605*F605 -> 4009.5
A606: Aldi | B606: ChIJYwJgnAn55IcR4YoA1cobq30 | C606: ALDI | D606: 1860 Edgewood Rd SW, Cedar Rapids, IA 52404, United States | E606: 4.5 | F606: 877 | G606: =E606*F606 -> 3946.5
A607: Aldi | B607: ChIJA-qDpt8d5ocRJByHGCsGq_M | C607: ALDI | D607: 940 N Quincy Ave, Ottumwa, IA 52501, United States | E607: 4.5 | F607: 357 | G607: =E607*F607 -> 1606.5
A608: Aldi | B608: ChIJyew6aZfx6IcRI5Aiv0r07tI | C608: ALDI | D608: 215 S Main St, Centerville, IA 52544, United States | E608: 4.6 | F608: 326 | G608: =E608*F608 -> 1499.6
A609: Aldi | B609: ChIJbzSbpiMy4YcRNVUS701PZis | C609: ALDI | D609: 3135 E Agency St, Burlington, IA 52601, United States | E609: 4.6 | F609: 492 | G609: =E609*F609 -> 2263.2
A610: Aldi | B610: ChIJbxUUwm_J5ocR0_N0vwFTIGo | C610: ALDI | D610: 927 Ave G, Fort Madison, IA 52627, United States | E610: 4.5 | F610: 319 | G610: =E610*F610 -> 1435.5
A611: Aldi | B611: ChIJc8LoJao754cRiHhBe9kuFZk | C611: ALDI | D611: 3379 Main St, Keokuk, IA 52632, United States | E611: 4.6 | F611: 209 | G611: =E611*F611 -> 961.4
A612: Aldi | B612: ChIJA6M1aZWh5ocRZZdJel-4UG4 | C612: ALDI | D612: 1309 E Washington St, Mt Pleasant, IA 52641, United States | E612: 4.5 | F612: 257 | G612: =E612*F612 -> 1156.5
A613: Aldi | B613: ChIJL_HfDuxm4ocRht8AQQvbilA | C613: ALDI | D613: 2575 Lincoln Way, Clinton, IA 52732, United States | E613: 4.5 | F613: 295 | G613: =E613*F613 -> 1327.5
A614: Aldi | B614: ChIJa9_mYgrv44cRtKUZafE2xHg | C614: ALDI | D614: 3200 N Port Dr, Muscatine, IA 52761, United States | E614: 4.6 | F614: 555 | G614: =E614*F614 -> 2553
... A623: Aldi | B623: ChIJx0HgBHnID4gRCvE9Eueo80k | C623: ALDI | D623: 7905 Golf Rd, Morton Grove, IL 60053, United States | E623: 4.4 | F623: 455 | G623: =E623*F623 -> 2002
A624: Aldi | B624: ChIJe1UE9PC5D4gRX7QAsi4bRxE | C624: Aldi | D624: 730 E Rand Rd, Mt Prospect, IL 60056, United States | G624: =E624*F624 -> 0
A625: Aldi | B625: ChIJ2zr7XS6YD4gRABABXL25I-U | C625: ALDI | D625: 730 S Illinois 83, Mundelein, IL 60060, United States | E625: 4.6 | F625: 550 | G625: =E625*F625 -> 2530
A626: Aldi | B626: ChIJSxfttbK7D4gRNGILdMOgwHg | C626: ALDI | D626: 1432 E Rand Rd, Prospect Heights, IL 60070, United States | E626: 4.5 | F626: 377 | G626: =E626*F626 -> 1696.5
A627: Aldi | B627: ChIJO3w6mayED4gR_CpNd_PJHhs | C627: ALDI | D627: 74 W Rollins Rd, Round Lake Beach, IL 60073, United States | E627: 4.4 | F627: 1012 | G627: =E627*F627 -> 4452.8
A628: Aldi | B628: ChIJ09OFhBrPD4gR2IB9P3WRkPY | C628: ALDI | D628: 4833 Oakton St, Skokie, IL 60077, United States | E628: 4.4 | F628: 681 | G628: =E628*F628 -> 2996.4
A629: Aldi | B629: ChIJvyccNe6SD4gRK-hA6EsjFNU | C629: ALDI | D629: 1050 S Waukegan Rd, Waukegan, IL 60085, United States | E629: 4.4 | F629: 448 | G629: =E629*F629 -> 1971.2
A630: Aldi | B630: ChIJxTJQ53-7D4gRLB-ZUs18iR0 | C630: ALDI | D630: 1202 W Dundee Rd, Buffalo Grove, IL 60089, United States | E630: 4.4 | F630: 604 | G630: =E630*F630 -> 2657.6
A631: Aldi | B631: ChIJMxhnXge8D4gRm4Pf3gZfbjk | C631: Aldi | D631: 901 W Dundee Rd, Wheeling, IL 60090, United States | E631: 5 | F631: 1 | G631: =E631*F631 -> 5
A632: Aldi | B632: ChIJG30n53tpD4gRC0uR6a4rLZE | C632: ALDI | D632: 410 S Eastwood Dr, Woodstock, IL 60098, United States | E632: 4.5 | F632: 314 | G632: =E632*F632 -> 1413
A633: Aldi | B633: ChIJkTOcs3rzD4gRU26DFlN-GZ4 | C633: ALDI | D633: 2861 Sheridan Rd, Zion, IL 60099, United States | E633: 4.5 | F633: 576 | G633: =E633*F633 -> 2592
A634: Aldi | B634: ChIJQYXRPG4SD4gR55Yvrr6eA_M | C634: ALDI | D634: 425 S Randall Rd, Algonquin, IL 60102, United States | E634: 4.5 | F634: 330 | G634: =E634*F634 -> 1485
A635: Aldi | B635: ChIJB4IoX8NKDogRt_qvRMadkMA | C635: ALDI | D635: 400 S Mannheim Rd, Bellwood, IL 60104, United States | E635: 4.3 | F635: 549 | G635: =E635*F635 -> 2360.7
...
